Internal Server Error: /register/
Traceback (most recent call last):
  File "C:\Users\Admin\.virtualenvs\instagram-close-friends-m9cJIEkB\Lib\site-packages\django\db\backends\utils.py", line 105, in _execute
    return self.cursor.execute(sql, params)
           ^^^^^^^^^^^^^^^^^^^^^^^^^^^^^^^^
  File "C:\Users\Admin\.virtualenvs\instagram-close-friends-m9cJIEkB\Lib\site-packages\django\db\backends\sqlite3\base.py", line 354, in execute
    return super().execute(query, params)
           ^^^^^^^^^^^^^^^^^^^^^^^^^^^^^^
sqlite3.IntegrityError: UNIQUE constraint failed: Core_user.email

The above exception was the direct cause of the following exception:

Traceback (most recent call last):
  File "C:\Users\Admin\.virtualenvs\instagram-close-friends-m9cJIEkB\Lib\site-packages\django\core\handlers\exception.py", line 55, in inner
    response = get_response(request)
               ^^^^^^^^^^^^^^^^^^^^^
  File "C:\Users\Admin\.virtualenvs\instagram-close-friends-m9cJIEkB\Lib\site-packages\django\core\handlers\base.py", line 197, in _get_response
    response = wrapped_callback(request, *callback_args, **callback_kwargs)
               ^^^^^^^^^^^^^^^^^^^^^^^^^^^^^^^^^^^^^^^^^^^^^^^^^^^^^^^^^^^^
  File "C:\Users\Admin\Desktop\projects\instagram-close-friends\backend\CloseFriends\Core\views.py", line 52, in Register
    User.objects.create_user(username=username, email=email, password=password)
  File "C:\Users\Admin\Desktop\projects\instagram-close-friends\backend\CloseFriends\Core\models.py", line 12, in create_user
    user.save(using=self._db)
  File "C:\Users\Admin\.virtualenvs\instagram-close-friends-m9cJIEkB\Lib\site-packages\django\contrib\auth\base_user.py", line 62, in save
    super().save(*args, **kwargs)
  File "C:\Users\Admin\.virtualenvs\instagram-close-friends-m9cJIEkB\Lib\site-packages\django\db\models\base.py", line 892, in save
    self.save_base(
  File "C:\Users\Admin\.virtualenvs\instagram-close-friends-m9cJIEkB\Lib\site-packages\django\db\models\base.py", line 998, in save_base
    updated = self._save_table(
              ^^^^^^^^^^^^^^^^^
  File "C:\Users\Admin\.virtualenvs\instagram-close-friends-m9cJIEkB\Lib\site-packages\django\db\models\base.py", line 1161, in _save_table
    results = self._do_insert(
              ^^^^^^^^^^^^^^^^
  File "C:\Users\Admin\.virtualenvs\instagram-close-friends-m9cJIEkB\Lib\site-packages\django\db\models\base.py", line 1202, in _do_insert
    return manager._insert(
           ^^^^^^^^^^^^^^^^
  File "C:\Users\Admin\.virtualenvs\instagram-close-friends-m9cJIEkB\Lib\site-packages\django\db\models\manager.py", line 87, in manager_method
    return getattr(self.get_queryset(), name)(*args, **kwargs)
           ^^^^^^^^^^^^^^^^^^^^^^^^^^^^^^^^^^^^^^^^^^^^^^^^^^^
  File "C:\Users\Admin\.virtualenvs\instagram-close-friends-m9cJIEkB\Lib\site-packages\django\db\models\query.py", line 1847, in _insert
    return query.get_compiler(using=using).execute_sql(returning_fields)
           ^^^^^^^^^^^^^^^^^^^^^^^^^^^^^^^^^^^^^^^^^^^^^^^^^^^^^^^^^^^^^
  File "C:\Users\Admin\.virtualenvs\instagram-close-friends-m9cJIEkB\Lib\site-packages\django\db\models\sql\compiler.py", line 1836, in execute_sql
    cursor.execute(sql, params)
  File "C:\Users\Admin\.virtualenvs\instagram-close-friends-m9cJIEkB\Lib\site-packages\django\db\backends\utils.py", line 122, in execute
    return super().execute(sql, params)
           ^^^^^^^^^^^^^^^^^^^^^^^^^^^^
  File "C:\Users\Admin\.virtualenvs\instagram-close-friends-m9cJIEkB\Lib\site-packages\django\db\backends\utils.py", line 79, in execute
    return self._execute_with_wrappers(
           ^^^^^^^^^^^^^^^^^^^^^^^^^^^^
  File "C:\Users\Admin\.virtualenvs\instagram-close-friends-m9cJIEkB\Lib\site-packages\django\db\backends\utils.py", line 92, in _execute_with_wrappers
    return executor(sql, params, many, context)
           ^^^^^^^^^^^^^^^^^^^^^^^^^^^^^^^^^^^^
  File "C:\Users\Admin\.virtualenvs\instagram-close-friends-m9cJIEkB\Lib\site-packages\django\db\backends\utils.py", line 100, in _execute
    with self.db.wrap_database_errors:
  File "C:\Users\Admin\.virtualenvs\instagram-close-friends-m9cJIEkB\Lib\site-packages\django\db\utils.py", line 91, in __exit__
    raise dj_exc_value.with_traceback(traceback) from exc_value
  File "C:\Users\Admin\.virtualenvs\instagram-close-friends-m9cJIEkB\Lib\site-packages\django\db\backends\utils.py", line 105, in _execute
    return self.cursor.execute(sql, params)
           ^^^^^^^^^^^^^^^^^^^^^^^^^^^^^^^^
  File "C:\Users\Admin\.virtualenvs\instagram-close-friends-m9cJIEkB\Lib\site-packages\django\db\backends\sqlite3\base.py", line 354, in execute
    return super().execute(query, params)
           ^^^^^^^^^^^^^^^^^^^^^^^^^^^^^^
django.db.utils.IntegrityError: UNIQUE constraint failed: Core_user.email
"POST /register/ HTTP/1.1" 500 168760
Internal Server Error: /forgot-password
Traceback (most recent call last):
  File "C:\Users\Admin\.virtualenvs\instagram-close-friends-m9cJIEkB\Lib\site-packages\django\db\backends\utils.py", line 105, in _execute
    return self.cursor.execute(sql, params)
           ^^^^^^^^^^^^^^^^^^^^^^^^^^^^^^^^
  File "C:\Users\Admin\.virtualenvs\instagram-close-friends-m9cJIEkB\Lib\site-packages\django\db\backends\sqlite3\base.py", line 354, in execute
    return super().execute(query, params)
           ^^^^^^^^^^^^^^^^^^^^^^^^^^^^^^
sqlite3.OperationalError: no such table: Core_passwordresetcode

The above exception was the direct cause of the following exception:

Traceback (most recent call last):
  File "C:\Users\Admin\.virtualenvs\instagram-close-friends-m9cJIEkB\Lib\site-packages\django\core\handlers\exception.py", line 55, in inner
    response = get_response(request)
               ^^^^^^^^^^^^^^^^^^^^^
  File "C:\Users\Admin\.virtualenvs\instagram-close-friends-m9cJIEkB\Lib\site-packages\django\core\handlers\base.py", line 197, in _get_response
    response = wrapped_callback(request, *callback_args, **callback_kwargs)
               ^^^^^^^^^^^^^^^^^^^^^^^^^^^^^^^^^^^^^^^^^^^^^^^^^^^^^^^^^^^^
  File "C:\Users\Admin\Desktop\projects\instagram-close-friends\backend\CloseFriends\Core\views.py", line 103, in ForgotPassword
    new_password_reset.save()
  File "C:\Users\Admin\.virtualenvs\instagram-close-friends-m9cJIEkB\Lib\site-packages\django\db\models\base.py", line 892, in save
    self.save_base(
  File "C:\Users\Admin\.virtualenvs\instagram-close-friends-m9cJIEkB\Lib\site-packages\django\db\models\base.py", line 998, in save_base
    updated = self._save_table(
              ^^^^^^^^^^^^^^^^^
  File "C:\Users\Admin\.virtualenvs\instagram-close-friends-m9cJIEkB\Lib\site-packages\django\db\models\base.py", line 1161, in _save_table
    results = self._do_insert(
              ^^^^^^^^^^^^^^^^
  File "C:\Users\Admin\.virtualenvs\instagram-close-friends-m9cJIEkB\Lib\site-packages\django\db\models\base.py", line 1202, in _do_insert
    return manager._insert(
           ^^^^^^^^^^^^^^^^
  File "C:\Users\Admin\.virtualenvs\instagram-close-friends-m9cJIEkB\Lib\site-packages\django\db\models\manager.py", line 87, in manager_method
    return getattr(self.get_queryset(), name)(*args, **kwargs)
           ^^^^^^^^^^^^^^^^^^^^^^^^^^^^^^^^^^^^^^^^^^^^^^^^^^^
  File "C:\Users\Admin\.virtualenvs\instagram-close-friends-m9cJIEkB\Lib\site-packages\django\db\models\query.py", line 1847, in _insert
    return query.get_compiler(using=using).execute_sql(returning_fields)
           ^^^^^^^^^^^^^^^^^^^^^^^^^^^^^^^^^^^^^^^^^^^^^^^^^^^^^^^^^^^^^
  File "C:\Users\Admin\.virtualenvs\instagram-close-friends-m9cJIEkB\Lib\site-packages\django\db\models\sql\compiler.py", line 1836, in execute_sql
    cursor.execute(sql, params)
  File "C:\Users\Admin\.virtualenvs\instagram-close-friends-m9cJIEkB\Lib\site-packages\django\db\backends\utils.py", line 122, in execute
    return super().execute(sql, params)
           ^^^^^^^^^^^^^^^^^^^^^^^^^^^^
  File "C:\Users\Admin\.virtualenvs\instagram-close-friends-m9cJIEkB\Lib\site-packages\django\db\backends\utils.py", line 79, in execute
    return self._execute_with_wrappers(
           ^^^^^^^^^^^^^^^^^^^^^^^^^^^^
  File "C:\Users\Admin\.virtualenvs\instagram-close-friends-m9cJIEkB\Lib\site-packages\django\db\backends\utils.py", line 92, in _execute_with_wrappers
    return executor(sql, params, many, context)
           ^^^^^^^^^^^^^^^^^^^^^^^^^^^^^^^^^^^^
  File "C:\Users\Admin\.virtualenvs\instagram-close-friends-m9cJIEkB\Lib\site-packages\django\db\backends\utils.py", line 100, in _execute
    with self.db.wrap_database_errors:
  File "C:\Users\Admin\.virtualenvs\instagram-close-friends-m9cJIEkB\Lib\site-packages\django\db\utils.py", line 91, in __exit__
    raise dj_exc_value.with_traceback(traceback) from exc_value
  File "C:\Users\Admin\.virtualenvs\instagram-close-friends-m9cJIEkB\Lib\site-packages\django\db\backends\utils.py", line 105, in _execute
    return self.cursor.execute(sql, params)
           ^^^^^^^^^^^^^^^^^^^^^^^^^^^^^^^^
  File "C:\Users\Admin\.virtualenvs\instagram-close-friends-m9cJIEkB\Lib\site-packages\django\db\backends\sqlite3\base.py", line 354, in execute
    return super().execute(query, params)
           ^^^^^^^^^^^^^^^^^^^^^^^^^^^^^^
django.db.utils.OperationalError: no such table: Core_passwordresetcode
"POST /forgot-password HTTP/1.1" 500 152733
Internal Server Error: /forgot-password
Traceback (most recent call last):
  File "C:\Users\Admin\.virtualenvs\instagram-close-friends-m9cJIEkB\Lib\site-packages\django\core\handlers\exception.py", line 55, in inner
    response = get_response(request)
               ^^^^^^^^^^^^^^^^^^^^^
  File "C:\Users\Admin\.virtualenvs\instagram-close-friends-m9cJIEkB\Lib\site-packages\django\core\handlers\base.py", line 197, in _get_response
    response = wrapped_callback(request, *callback_args, **callback_kwargs)
               ^^^^^^^^^^^^^^^^^^^^^^^^^^^^^^^^^^^^^^^^^^^^^^^^^^^^^^^^^^^^
  File "C:\Users\Admin\Desktop\projects\instagram-close-friends\backend\CloseFriends\Core\views.py", line 120, in ForgotPassword
    return redirect(f"{reverse('forgot-pasword')}?password_reset_sent=True")
                       ^^^^^^^^^^^^^^^^^^^^^^^^^
  File "C:\Users\Admin\.virtualenvs\instagram-close-friends-m9cJIEkB\Lib\site-packages\django\urls\base.py", line 88, in reverse
    return resolver._reverse_with_prefix(view, prefix, *args, **kwargs)
           ^^^^^^^^^^^^^^^^^^^^^^^^^^^^^^^^^^^^^^^^^^^^^^^^^^^^^^^^^^^^
  File "C:\Users\Admin\.virtualenvs\instagram-close-friends-m9cJIEkB\Lib\site-packages\django\urls\resolvers.py", line 831, in _reverse_with_prefix
    raise NoReverseMatch(msg)
django.urls.exceptions.NoReverseMatch: Reverse for 'forgot-pasword' not found. 'forgot-pasword' is not a valid view function or pattern name.
"POST /forgot-password HTTP/1.1" 500 81769
